Workbook

Sheet Post Customer Addition
B1: Recovery Targets 2026 (Post Customer Transfer)
A2: Sales Person | B2: JAN | C2: FEB | D2: MAR | E2: APR | F2: MAY | G2: JUN | H2: JUL | I2: AUG | J2: SEP | K2: OCT | L2: NOV | M2: DEC | N2: Total
A3: Farhan Shah | B3: 44320520 | C3: 50122943 | D3: 46791649 | E3: 48838866 | F3: 41265635 | G3: 30285017 | H3: 44429246 | I3: 36881097 | J3: 51734802 | K3: 53216988 | L3: 53481017 | M3: 47792570 | N3: =SUM(B3:M3) -> 5.4916035e+08
A4: Hassan Shafi | B4: 31402775 | C4: 35514012 | D4: 33153664 | E4: 34604195 | F4: 30265057 | G4: 23018764 | H4: 32383332 | I4: 26953363 | J4: 37683409 | K4: 38885281 | L4: 39001546 | M4: 35040882 | N4: =SUM(B4:M4) -> 3.9790628e+08
A5: M. Ali | B5: 5773755.2 | C5: 6529652.7 | D5: 6095675.9 | E5: 6362372.5 | F5: 5375787 | G5: 4075584.6 | H5: 5787919.2 | I5: 4804601.2 | J5: 6967118.2 | K5: 6932722.3 | L5: 6967118.2 | M5: 6967118.2 | N5: =SUM(B5:M5) -> 72639425
A6: Mobeen | B6: 30327958 | C6: 34298481 | D6: 32018920 | E6: 33419804 | F6: 53801370 | G6: 41623626 | H6: 50097294 | I6: 45695155 | J6: 60978953 | K6: 65769734 | L6: 64187465 | M6: 62033175 | N6: =SUM(B6:M6) -> 5.7425193e+08
A7: Shabbir | B7: 18472071 | C7: 20890427 | D7: 19501998 | E7: 20355245 | F7: 85608152 | G7: 70298320 | H7: 79010071 | I7: 73478297 | J7: 94210352 | K7: 1.0555466e+08 | L7: 1.006574e+08 | M7: 1.032237e+08 | N7: =SUM(B7:M7) -> 7.912607e+08
A8: Bilal | F8: 299664.91 | G8: 248695.09 | H8: 263690.65 | I8: 239812.03 | J8: 299825.13 | K8: 344094.57 | L8: 323428.98 | M8: 343805.04 | N8: =SUM(B8:M8) -> 2363016.4
A9: Commercial | B9: =SUM(B3:B8) -> 1.3029708e+08 | C9: =SUM(C3:C8) -> 1.4735552e+08 | D9: =SUM(D3:D8) -> 1.3756191e+08 | E9: =SUM(E3:E8) -> 1.4358048e+08 | F9: =SUM(F3:F8) -> 2.1661567e+08 | G9: =SUM(G3:G8) -> 1.6955001e+08 | H9: =SUM(H3:H8) -> 2.1197155e+08 | I9: =SUM(I3:I8) -> 1.8805232e+08 | ... M9: =SUM(M3:M8) -> 2.5540125e+08 | N9: =SUM(B9:M9) -> 2.3875817e+09
A10: Ali Raza | B10: 31355887 | C10: 36385831 | D10: 32007876 | E10: 26926962 | F10: 31259998 | G10: 26609873 | H10: 26942061 | I10: 30187037 | J10: 31485600 | K10: 31055652 | L10: 33649398 | M10: 33752814 | N10: =SUM(B10:M10) -> 3.7161899e+08
A11: Adnan | B11: 42298036 | C11: 49083262 | D11: 43177548 | E11: 36323565 | F11: 41637938 | G11: 35455351 | H11: 35876902 | I11: 40296558 | J11: 41941985 | K11: 41283592 | L11: 39232837 | M11: 44922486 | N11: =SUM(B11:M11) -> 4.9153006e+08
A12: Asim | B12: 50905839 | C12: 59071882 | D12: 51964335 | E12: 43715542 | F12: 48280988 | G12: 40151557 | H12: 41567299 | I12: 47032227 | J12: 48645931 | K12: 47583144 | L12: 48645931 | M12: 48645931 | N12: =SUM(B12:M12) -> 5.7621061e+08
A13: Sheryar Anwar | B13: 28651069 | C13: 33247120 | D13: 29246816 | E13: 24604191 | F13: 27173737 | G13: 23161117 | H13: 23395107 | I13: 26470903 | J13: 27379136 | K13: 26780974 | L13: 25462916 | M13: 22794404 | N13: =SUM(B13:M13) -> 3.1836749e+08
A14: Usman | B14: 15770538 | C14: 18300364 | D14: 16098458 | E14: 13542997 | F14: 15697935 | G14: 13363287 | H14: 13529142 | I14: 15163155 | J14: 15811390 | K14: 19150736 | L14: 19099664 | M14: 13396484 | N14: =SUM(B14:M14) -> 1.8892415e+08
A15: Corporate | B15: =SUM(B10:B14) -> 1.6898137e+08 | C15: =SUM(C10:C14) -> 1.9608846e+08 | D15: =SUM(D10:D14) -> 1.7249503e+08 | E15: =SUM(E10:E14) -> 1.4511326e+08 | F15: =SUM(F10:F14) -> 1.640506e+08 | G15: =SUM(G10:G14) -> 1.3874119e+08 | H15: =SUM(H10:H14) -> 1.4131051e+08 | I15: =SUM(I10:I14) -> 1.5914988e+08 | ... N15: =SUM(N10:N14) -> 1.9466513e+09
A16: ASQ | B16: 1.1394559e+08 | C16: 1.1757849e+08 | D16: 1.2434577e+08 | E16: 1.1341083e+08 | F16: 5144814.1 | G16: 4003573.9 | H16: 4621746.4 | I16: 4538846 | J16: 5498436.9 | K16: 5811835.2 | L16: 5795087.3 | M16: 5633870.2 | N16: =SUM(B16:M16) -> 5.1032889e+08
A17: KHQ | B17: 1757045.8 | C17: 1666786.2 | D17: 1762718.7 | E17: 1749465 | F17: 1782513.6 | G17: 1387110.3 | H17: 1601287.3 | I17: 1572565 | J17: 1905032.6 | K17: 2013615 | L17: 2007812.4 | M17: 1951955.9 | N17: =SUM(B17:M17) -> 21157908
A18: AWQ | B18: 460338.77 | C18: 436691.12 | D18: 461825.05 | E18: 458352.63 | F18: 455978.34 | G18: 354831.67 | H18: 409619.52 | I18: 402272.16 | J18: 487319.48 | K18: 515095.58 | L18: 513611.23 | M18: 499322.77 | N18: =SUM(B18:M18) -> 5455258.3
A19: WJQ | B19: 42958148 | C19: 40751384 | D19: 43096846 | E19: 42772805 | F19: 24997091 | G19: 19452151 | H19: 22455664 | I19: 22052876 | J19: 26715237 | K19: 28237945 | L19: 28156571 | M19: 27373267 | N19: =SUM(B19:M19) -> 3.6901999e+08
A20: WZQ | B20: 553856.68 | C20: 525405.01 | D20: 555644.9 | E20: 551467.06 | F20: 548610.43 | G20: 426915.79 | H20: 492833.8 | I20: 483993.83 | J20: 586318.53 | K20: 619737.35 | L20: 617951.45 | M20: 600760.28 | N20: =SUM(B20:M20) -> 6563495.1
A21: Directors | B21: =SUM(B16:B20) -> 1.5967498e+08 | C21: =SUM(C16:C20) -> 1.6095876e+08 | D21: =SUM(D16:D20) -> 1.7022281e+08 | E21: =SUM(E16:E20) -> 1.5894292e+08 | F21: =SUM(F16:F20) -> 32929008 | G21: =SUM(G16:G20) -> 25624583 | H21: =SUM(H16:H20) -> 29581151 | I21: =SUM(I16:I20) -> 29050553 | ... N21: =SUM(N16:N20) -> 9.1252554e+08
A22: AAB | B22: 44145660 | C22: 48032680 | D22: 43430492 | E22: 37656261 | F22: 35861707 | G22: 22960761 | H22: 29112692 | I22: 29347093 | J22: 37456120 | K22: 39024632 | L22: 40775501 | M22: 38517135 | N22: =SUM(B22:M22) -> 4.4632073e+08
A23: Abdul Rafay | B23: 17291088 | C23: 18813567 | D23: 17010969 | E23: 14749303 | F23: 23228500 | G23: 18834303 | H23: 21939459 | I23: 25864579 | J23: 23141063 | K23: 32885462 | L23: 30647472 | M23: 40729182 | N23: =SUM(B23:M23) -> 2.8513495e+08
A24: Asim Javed | B24: 17297444 | C24: 18820482 | D24: 17017223 | E24: 14754725 | N24: =SUM(B24:M24) -> 67889874
A25: Ghouri, Mr. Mubeen Khan | B25: 12835088 | C25: 13965217 | D25: 12627158 | E25: 10948334 | F25: 10426578 | G25: 8908352.8 | H25: 9120898.7 | I25: 8753919.8 | J25: 13474925 | K25: 17509784 | L25: 15408206 | M25: 13293742 | N25: =SUM(B25:M25) -> 1.472722e+08
A26: Imran Shah | B26: 46099571 | C26: 50158633 | D26: 45352750 | E26: 39322948 | F26: 36579119 | G26: 23202410 | H26: 32890985 | I26: 24845172 | J26: 33624136 | K26: 38602763 | L26: 39510371 | M26: 45189002 | N26: =SUM(B26:M26) -> 4.5537786e+08
A27: Shahzaib | F27: 8029562.7 | G27: 5093212 | H27: 7219972.4 | I27: 5453818.3 | J27: 7380908 | K27: 8473777.2 | L27: 8673008.3 | M27: 9919537 | N27: =SUM(B27:M27) -> 60243796
A28: Kashif | B28: 1740497.6 | C28: 1893748.2 | D28: 1712301.2 | E28: 1484645 | F28: 1413892.4 | G28: 905256.57 | H28: 1147804.1 | I28: 1157045.7 | J28: 1476754.2 | K28: 1538594.7 | L28: 1607624.9 | M28: 1518586 | N28: =SUM(B28:M28) -> 17596751
A29: Abdullah Rauf | F29: 12880479 | G29: 9830792.2 | H29: 11089882 | I29: 7971742.1 | J29: 9329499.2 | K29: 20481161 | L29: 16164427 | M29: 14294708 | N29: =SUM(B29:M29) -> 1.0204269e+08
A30: Tajammul Ahmed | B30: 53106375 | C30: 57782386 | D30: 52246042 | E30: 45299754 | F30: 43478816 | G30: 27672069 | H30: 30169624 | I30: 26934505 | J30: 42419921 | K30: 45721334 | L30: 57290744 | M30: 61051034 | N30: =SUM(B30:M30) -> 5.431726e+08
A31: Umair Quadri | B31: 23676741 | C31: 25761476 | D31: 23293174 | E31: 20196267 | F31: 16209058 | G31: 11273623 | H31: 14674366 | I31: 15782611 | J31: 17679165 | K31: 19467497 | L31: 21432442 | M31: 21660172 | N31: =SUM(B31:M31) -> 2.3110659e+08
A32: Waqar Ali | B32: 11466430 | C32: 12476048 | D32: 11280672 | E32: 9780868.4 | F32: 9240018.8 | G32: 5427059.9 | H32: 8495228.5 | I32: 7996157.9 | J32: 8465258.2 | K32: 10645447 | L32: 9647334.5 | M32: 11955894 | N32: =SUM(B32:M32) -> 1.1687642e+08
A33: South | B33: =SUM(B22:B32) -> 2.276589e+08 | C33: =SUM(C22:C32) -> 2.4770424e+08 | D33: =SUM(D22:D32) -> 2.2397078e+08 | E33: =SUM(E22:E32) -> 1.9419311e+08 | F33: =SUM(F22:F32) -> 1.9734773e+08 | G33: =SUM(G22:G32) -> 1.3410784e+08 | H33: =SUM(H22:H32) -> 1.6586091e+08 | I33: =SUM(I22:I32) -> 1.5410664e+08 | ... N33: =SUM(N22:N32) -> 2.4730345e+09
A34: Sheeraz, | B34: 9682329.8 | C34: 10248872 | D34: 12474593 | E34: 12156738 | F34: 12920980 | G34: 10573767 | H34: 11694323 | I34: 13887570 | J34: 14260946 | K34: 16183404 | L34: 15410241 | M34: 15635222 | N34: =SUM(B34:M34) -> 1.5512899e+08
A35: Aqib, Mr. Muhammad | B35: 5998205.4 | C35: 6349178.3 | D35: 8834658.9 | E35: 8834658.9 | F35: 8834658.9 | G35: 8834658.9 | H35: 7244635.7 | I35: 8603352.9 | J35: 8834658.9 | K35: 10025622 | L35: 9546647.4 | M35: 10025622 | N35: =SUM(B35:M35) -> 1.0196656e+08
A36: Fahad Khan | B36: 6817604.6 | C36: 6817604.6 | D36: 6817604.6 | E36: 6817604.6 | F36: 3007766.7 | G36: 3007766.7 | H36: 3007766.7 | I36: 3007766.7 | J36: 3007766.7 | K36: 3007766.7 | L36: 3007766.7 | M36: 3007766.7 | N36: =SUM(B36:M36) -> 51332552
A37: Ahmed Dawood | F37: 2005177.8 | G37: 2005177.8 | H37: 2005177.8 | I37: 2005177.8 | J37: 2005177.8 | K37: 2005177.8 | L37: 2005177.8 | M37: 2005177.8 | N37: =SUM(B37:M37) -> 16041422
A38: Waqar Ahmed | F38: 1804660 | G38: 1804660 | H38: 1804660 | I38: 1804660 | J38: 1804660 | K38: 1804660 | L38: 1804660 | M38: 1804660 | N38: =SUM(B38:M38) -> 14437280
A39: Faazil | F39: 500000 | G39: 500000 | H39: 500000 | I39: 500000 | J39: 500000 | K39: 500000 | L39: 500000 | M39: 500000 | N39: =SUM(B39:M39) -> 4000000
A40: Usama | F40: 500000 | G40: 500000 | H40: 500000 | I40: 500000 | J40: 500000 | K40: 500000 | L40: 500000 | M40: 500000 | N40: =SUM(B40:M40) -> 4000000
...

Sheet Recovery Targets
B1: Recovery Targets 2026 (Post Customer Transfer)
A2: Sales Person | B2: JAN | C2: FEB | D2: MAR | E2: APR | F2: MAY | G2: JUN | H2: JUL | I2: AUG | J2: SEP | K2: OCT | L2: NOV | M2: DEC | N2: Total
A3: Farhan Shah | G3: ='Post Customer Addition'!G3 -> 30285017 | H3: ='Post Customer Addition'!H3*1.1 -> 48872171 | I3: ='Post Customer Addition'!I3*0.9 -> 33192987 | J3: ='Post Customer Addition'!J3*0.9 -> 46561322 | K3: 47895289 | L3: 47132916 | M3: ='Post Customer Addition'!M3*1.15 -> 54961455 | N3: =SUM(B3:M3) -> 3.0890116e+08
A4: Hassan Shafi | G4: ='Post Customer Addition'!G4 -> 23018764 | H4: ='Post Customer Addition'!H4*1.1 -> 35621665 | I4: ='Post Customer Addition'!I4*0.95 -> 25605694 | J4: ='Post Customer Addition'!J4*0.95 -> 35799239 | K4: 34996753 | L4: 34101392 | M4: ='Post Customer Addition'!M4*1.15 -> 40297014 | N4: =SUM(B4:M4) -> 2.2944052e+08
A5: M. Ali | G5: ='Post Customer Addition'!G5 -> 4075584.6 | H5: 5787919.2 | I5: 4804601.2 | J5: 6967118.2 | K5: 6932722.3 | L5: 6967118.2 | M5: 6967118.2 | N5: =SUM(B5:M5) -> 42502182
A6: Mobeen | G6: ='Post Customer Addition'!G6 -> 41623626 | H6: ='Post Customer Addition'!H6*1.1 -> 55107023 | I6: ='Post Customer Addition'!I6*0.95 -> 43410397 | J6: ='Post Customer Addition'!J6*0.95 -> 57930006 | K6: 59192760 | L6: 55768718 | M6: ='Post Customer Addition'!M6*1.15 -> 71338151 | N6: =SUM(B6:M6) -> 3.8437068e+08
A7: Shabbir | G7: ='Post Customer Addition'!G7 -> 70298320 | H7: ='Post Customer Addition'!H7*1.1 -> 86911078 | I7: ='Post Customer Addition'!I7*0.93 -> 68334816 | J7: ='Post Customer Addition'!J7*0.93 -> 87615627 | K7: 94999197 | L7: 90091660 | M7: ='Post Customer Addition'!M7*1.1 -> 1.1354607e+08 | N7: =SUM(B7:M7) -> 6.1179677e+08
A8: Bilal | G8: ='Post Customer Addition'!G8 -> 248695.09 | H8: ='Post Customer Addition'!H8*1.1 -> 290059.72 | I8: ='Post Customer Addition'!I8*0.95 -> 227821.43 | J8: ='Post Customer Addition'!J8*0.95 -> 284833.87 | K8: 344094.57 | L8: 323428.98 | M8: ='Post Customer Addition'!M8*1.1 -> 378185.54 | N8: =SUM(B8:M8) -> 2097119.2
A9: Commercial | B9: =SUM(B3:B8) -> 0 | C9: =SUM(C3:C8) -> 0 | D9: =SUM(D3:D8) -> 0 | E9: =SUM(E3:E8) -> 0 | G9: =SUM(G3:G8) -> 1.6955001e+08 | H9: =SUM(H3:H8) -> 2.3258992e+08 | I9: =SUM(I3:I8) -> 1.7557632e+08 | J9: =SUM(J3:J8) -> 2.3515815e+08 | K9: =SUM(K3:K8) -> 2.4436082e+08 | L9: =SUM(L3:L8) -> 2.3438523e+08 | M9: =SUM(M3:M8) -> 2.8748799e+08 | N9: =SUM(B9:M9) -> 1.5791084e+09
A10: Ali Raza | G10: ='Post Customer Addition'!G10 -> 26609873 | H10: ='Post Customer Addition'!H10*1.1 -> 29636267 | I10: ='Post Customer Addition'!I10*0.95 -> 28677685 | J10: ='Post Customer Addition'!J10*0.95 -> 29911320 | K10: 27950087 | L10: 30284458 | M10: ='Post Customer Addition'!M10*1.1 -> 37128095 | N10: =SUM(B10:M10) -> 2.1019779e+08
A11: Adnan | G11: ='Post Customer Addition'!G11 -> 35455351 | H11: ='Post Customer Addition'!H11*1.1 -> 39464593 | I11: ='Post Customer Addition'!I11*0.95 -> 38281730 | J11: ='Post Customer Addition'!J11*0.95 -> 39844886 | K11: 37155233 | L11: 35309553 | M11: ='Post Customer Addition'!M11*1.1 -> 49414734 | N11: =SUM(B11:M11) -> 2.7492608e+08
A12: Asim | G12: ='Post Customer Addition'!G12 -> 40151557 | H12: ='Post Customer Addition'!H12*1.1 -> 45724029 | I12: ='Post Customer Addition'!I12*0.95 -> 44680615 | J12: ='Post Customer Addition'!J12*0.95 -> 46213634 | K12: 42824830 | L12: 43781337 | M12: ='Post Customer Addition'!M12*1.1 -> 53510524 | N12: =SUM(B12:M12) -> 3.1688653e+08
A13: Sheryar Anwar | G13: ='Post Customer Addition'!G13 -> 23161117 | H13: 23395107 | I13: 26470903 | J13: 27379136 | K13: 26780974 | L13: 25462916 | M13: ='Post Customer Addition'!M13 -> 22794404 | N13: =SUM(B13:M13) -> 1.7544456e+08
A14: Usman | G14: ='Post Customer Addition'!G14 -> 13363287 | H14: ='Post Customer Addition'!H14*1.1 -> 14882057 | I14: ='Post Customer Addition'!I14*0.95 -> 14404997 | J14: ='Post Customer Addition'!J14*0.95 -> 15020820 | K14: 17235662 | L14: 17189698 | M14: ='Post Customer Addition'!M14*1.1 -> 14736132 | N14: =SUM(B14:M14) -> 1.0683265e+08
A15: Corporate | B15: =SUM(B10:B14) -> 0 | C15: =SUM(C10:C14) -> 0 | D15: =SUM(D10:D14) -> 0 | E15: =SUM(E10:E14) -> 0 | G15: =SUM(G10:G14) -> 1.3874119e+08 | H15: =SUM(H10:H14) -> 1.5310205e+08 | I15: =SUM(I10:I14) -> 1.5251593e+08 | J15: =SUM(J10:J14) -> 1.583698e+08 | K15: =SUM(K10:K14) -> 1.5194678e+08 | L15: =SUM(L10:L14) -> 1.5202796e+08 | M15: =SUM(M10:M14) -> 1.7758389e+08 | N15: =SUM(N10:N14) -> 1.0842876e+09
A16: ASQ | G16: ='Post Customer Addition'!G16 -> 4003573.9 | H16: ='Post Customer Addition'!H16*1.1 -> 5083921 | I16: ='Post Customer Addition'!I16*0.95 -> 4311903.7 | J16: ='Post Customer Addition'!J16*0.95 -> 5223515.1 | K16: 5230651.7 | L16: 5215578.6 | M16: ='Post Customer Addition'!M16*1.1 -> 6197257.2 | N16: =SUM(B16:M16) -> 35266401
A17: KHQ | G17: ='Post Customer Addition'!G17 -> 1387110.3 | H17: ='Post Customer Addition'!H17*1.1 -> 1761416.1 | I17: ='Post Customer Addition'!I17*0.95 -> 1493936.7 | J17: ='Post Customer Addition'!J17*0.95 -> 1809780.9 | K17: 1812253.5 | L17: 1807031.2 | M17: ='Post Customer Addition'!M17*1.1 -> 2147151.4 | N17: =SUM(B17:M17) -> 12218680
A18: AWQ | G18: ='Post Customer Addition'!G18 -> 354831.67 | H18: ='Post Customer Addition'!H18*1.1 -> 450581.47 | I18: ='Post Customer Addition'!I18*0.95 -> 382158.55 | J18: ='Post Customer Addition'!J18*0.95 -> 462953.51 | K18: 463586.02 | L18: 462250.11 | M18: ='Post Customer Addition'!M18*1.1 -> 549255.04 | N18: =SUM(B18:M18) -> 3125616.4
A19: WJQ | G19: ='Post Customer Addition'!G19 -> 19452151 | H19: ='Post Customer Addition'!H19*1.1 -> 24701230 | I19: ='Post Customer Addition'!I19*0.95 -> 20950232 | J19: ='Post Customer Addition'!J19*0.95 -> 25379475 | K19: 25414150 | L19: 25340914 | M19: ='Post Customer Addition'!M19*1.1 -> 30110593 | N19: =SUM(B19:M19) -> 1.7134875e+08
A20: WZQ | G20: ='Post Customer Addition'!G20 -> 426915.79 | H20: ='Post Customer Addition'!H20*1.1 -> 542117.18 | I20: ='Post Customer Addition'!I20*0.95 -> 459794.14 | J20: ='Post Customer Addition'!J20*0.95 -> 557002.61 | K20: 557763.61 | L20: 556156.31 | M20: ='Post Customer Addition'!M20*1.1 -> 660836.31 | N20: =SUM(B20:M20) -> 3760585.9
A21: Directors | B21: =SUM(B16:B20) -> 0 | C21: =SUM(C16:C20) -> 0 | D21: =SUM(D16:D20) -> 0 | E21: =SUM(E16:E20) -> 0 | G21: =SUM(G16:G20) -> 25624583 | H21: =SUM(H16:H20) -> 32539266 | I21: =SUM(I16:I20) -> 27598025 | J21: =SUM(J16:J20) -> 33432728 | K21: =SUM(K16:K20) -> 33478405 | L21: =SUM(L16:L20) -> 33381930 | M21: =SUM(M16:M20) -> 39665093 | N21: =SUM(N16:N20) -> 2.2572003e+08
A22: AAB | G22: ='Post Customer Addition'!G22 -> 22960761 | H22: ='Post Customer Addition'!H22*1.1 -> 32023962 | I22: ='Post Customer Addition'!I22*0.95 -> 27879739 | J22: ='Post Customer Addition'!J22*0.95 -> 35583314 | K22: 35122169 | L22: 36697951 | M22: ='Post Customer Addition'!M22*1.1 -> 42368848 | N22: =SUM(B22:M22) -> 2.3263674e+08
A23: Abdul Rafay | G23: ='Post Customer Addition'!G23 -> 18834303 | H23: ='Post Customer Addition'!H23*1.1 -> 24133405 | I23: ='Post Customer Addition'!I23*0.95 -> 24571350 | J23: ='Post Customer Addition'!J23*0.95 -> 21984009 | K23: 29596915 | L23: 26582725 | M23: ='Post Customer Addition'!M23*1.1 -> 44802100 | N23: =SUM(B23:M23) -> 1.9050481e+08
A24: Asim Javed | G24: ='Post Customer Addition'!G24 -> 0 | H24: ='Post Customer Addition'!H24*1.1 -> 0 | I24: ='Post Customer Addition'!I24*0.95 -> 0 | J24: ='Post Customer Addition'!J24*0.95 -> 0 | K24: 0 | L24: 0 | M24: ='Post Customer Addition'!M24*1.1 -> 0 | N24: =SUM(B24:M24) -> 0
A25: Ghouri, Mr. Mubeen Khan | G25: ='Post Customer Addition'!G25 -> 8908352.8 | H25: ='Post Customer Addition'!H25*1.1 -> 10032989 | I25: ='Post Customer Addition'!I25*0.95 -> 8316223.9 | J25: ='Post Customer Addition'!J25*0.95 -> 12801179 | K25: 15758805 | L25: 13867385 | M25: ='Post Customer Addition'!M25*1.1 -> 14623116 | N25: =SUM(B25:M25) -> 84308051
A26: Imran Shah | G26: ='Post Customer Addition'!G26 -> 23202410 | H26: ='Post Customer Addition'!H26*1.1 -> 36180084 | I26: ='Post Customer Addition'!I26*0.95 -> 23602914 | J26: ='Post Customer Addition'!J26*0.95 -> 31942929 | K26: 34742487 | L26: 34559334 | M26: ='Post Customer Addition'!M26*1.1 -> 49707902 | N26: =SUM(B26:M26) -> 2.3393806e+08
A27: Shahzaib | G27: ='Post Customer Addition'!G27 -> 5093212 | H27: ='Post Customer Addition'!H27*1.1 -> 7941969.7 | I27: ='Post Customer Addition'!I27*0.95 -> 5181127.4 | J27: ='Post Customer Addition'!J27*0.95 -> 7011862.6 | K27: 8473777.2 | L27: 8673008.3 | M27: ='Post Customer Addition'!M27*1.1 -> 10911491 | N27: =SUM(B27:M27) -> 53286448
A28: Kashif | G28: ='Post Customer Addition'!G28 -> 905256.57 | H28: ='Post Customer Addition'!H28*1.1 -> 1262584.6 | I28: ='Post Customer Addition'!I28*0.95 -> 1099193.4 | J28: ='Post Customer Addition'!J28*0.95 -> 1402916.5 | K28: 1384735.2 | L28: 1446862.4 | M28: ='Post Customer Addition'!M28*1.1 -> 1670444.6 | N28: =SUM(B28:M28) -> 9171993.2
A29: Abdullah Rauf | G29: ='Post Customer Addition'!G29 -> 9830792.2 | H29: ='Post Customer Addition'!H29*1.1 -> 12198871 | I29: ='Post Customer Addition'!I29*0.95 -> 7573155 | J29: ='Post Customer Addition'!J29*0.95 -> 8863024.2 | K29: 18433045 | L29: 14547984 | M29: ='Post Customer Addition'!M29*1.1 -> 15724178 | N29: =SUM(B29:M29) -> 87171049
A30: Tajammul Ahmed | G30: ='Post Customer Addition'!G30 -> 27672069 | H30: ='Post Customer Addition'!H30*1.1 -> 33186586 | I30: ='Post Customer Addition'!I30*0.95 -> 25587780 | J30: ='Post Customer Addition'!J30*0.95 -> 40298925 | K30: 41149201 | L30: 50561670 | M30: ='Post Customer Addition'!M30*1.1 -> 67156137 | N30: =SUM(B30:M30) -> 2.8561237e+08
A31: Umair Quadri | G31: ='Post Customer Addition'!G31 -> 11273623 | H31: ='Post Customer Addition'!H31*1.1 -> 16141803 | I31: ='Post Customer Addition'!I31*0.95 -> 14993481 | J31: ='Post Customer Addition'!J31*0.95 -> 16795206 | K31: 17520747 | L31: 19189198 | M31: ='Post Customer Addition'!M31*1.1 -> 23826189 | N31: =SUM(B31:M31) -> 1.1974025e+08
A32: Waqar Ali | G32: ='Post Customer Addition'!G32 -> 5427059.9 | H32: ='Post Customer Addition'!H32*1.1 -> 9344751.4 | I32: ='Post Customer Addition'!I32*0.95 -> 7596350 | J32: ='Post Customer Addition'!J32*0.95 -> 8041995.3 | K32: 10645447 | L32: 9647334.5 | M32: ='Post Customer Addition'!M32*1.1 -> 13151484 | N32: =SUM(B32:M32) -> 63854422
A33: South | B33: =SUM(B22:B32) -> 0 | C33: =SUM(C22:C32) -> 0 | D33: =SUM(D22:D32) -> 0 | E33: =SUM(E22:E32) -> 0 | G33: =SUM(G22:G32) -> 1.3410784e+08 | H33: =SUM(H22:H32) -> 1.82447e+08 | I33: =SUM(I22:I32) -> 1.4640131e+08 | J33: =SUM(J22:J32) -> 1.8472536e+08 | K33: =SUM(K22:K32) -> 2.1282733e+08 | L33: =SUM(L22:L32) -> 2.1577345e+08 | M33: =SUM(M22:M32) -> 2.8394189e+08 | N33: =SUM(N22:N32) -> 1.3602242e+09
A34: Sheeraz, | G34: ='Post Customer Addition'!G34 -> 10573767 | H34: ='Post Customer Addition'!H34*1.1 -> 12863755 | I34: 13887570 | J34: 14260946 | K34: 16183404 | L34: 15410241 | M34: ='Post Customer Addition'!M34*1.1 -> 17198745 | N34: =SUM(B34:M34) -> 1.0037843e+08
A35: Aqib, Mr. Muhammad | G35: ='Post Customer Addition'!G35 -> 8834658.9 | H35: ='Post Customer Addition'!H35*1.1 -> 7969099.2 | I35: 8603352.9 | J35: 8834658.9 | K35: 10025622 | L35: 9546647.4 | M35: ='Post Customer Addition'!M35*1.1 -> 11028184 | N35: =SUM(B35:M35) -> 64842224
A36: Fahad Khan | G36: ='Post Customer Addition'!G36 -> 3007766.7 | H36: ='Post Customer Addition'!H36*1.1 -> 3308543.4 | I36: 3007766.7 | J36: 3007766.7 | K36: 3007766.7 | L36: 3007766.7 | M36: ='Post Customer Addition'!M36*1.1 -> 3308543.4 | N36: =SUM(B36:M36) -> 21655920
A37: Ahmed Dawood | G37: ='Post Customer Addition'!G37 -> 2005177.8 | H37: ='Post Customer Addition'!H37*1.1 -> 2205695.6 | I37: 2005177.8 | J37: 2005177.8 | K37: 2005177.8 | L37: 2005177.8 | M37: ='Post Customer Addition'!M37*1.1 -> 2205695.6 | N37: =SUM(B37:M37) -> 14437280
A38: Waqar Ahmed | G38: ='Post Customer Addition'!G38 -> 1804660 | H38: ='Post Customer Addition'!H38*1.1 -> 1985126 | I38: 1804660 | J38: 1804660 | K38: 1804660 | L38: 1804660 | M38: ='Post Customer Addition'!M38*1.1 -> 1985126 | N38: =SUM(B38:M38) -> 12993552
A39: Faazil | G39: ='Post Customer Addition'!G39 -> 500000 | H39: ='Post Customer Addition'!H39*1.1 -> 550000 | I39: 500000 | J39: 500000 | K39: 500000 | L39: 500000 | M39: ='Post Customer Addition'!M39*1.1 -> 550000 | N39: =SUM(B39:M39) -> 3600000
A40: Usama | G40: ='Post Customer Addition'!G40 -> 500000 | H40: ='Post Customer Addition'!H40*1.1 -> 550000 | I40: 500000 | J40: 500000 | K40: 500000 | L40: 500000 | M40: ='Post Customer Addition'!M40*1.1 -> 550000 | N40: =SUM(B40:M40) -> 3600000
...
